Internal Server Error: /
Traceback (most recent call last):
  File "C:\Users\Khusan Akhmedov\Documents\movie\.environment\Lib\site-packages\django\core\handlers\exception.py", line 55, in inner
    response = get_response(request)
               ^^^^^^^^^^^^^^^^^^^^^
  File "C:\Users\Khusan Akhmedov\Documents\movie\.environment\Lib\site-packages\django\core\handlers\base.py", line 197, in _get_response
    response = wrapped_callback(request, *callback_args, **callback_kwargs)
               ^^^^^^^^^^^^^^^^^^^^^^^^^^^^^^^^^^^^^^^^^^^^^^^^^^^^^^^^^^^^
  File "C:\Users\Khusan Akhmedov\Documents\movie\.environment\Lib\site-packages\django\views\generic\base.py", line 104, in view
    return self.dispatch(request, *args, **kwargs)
           ^^^^^^^^^^^^^^^^^^^^^^^^^^^^^^^^^^^^^^^
  File "C:\Users\Khusan Akhmedov\Documents\movie\.environment\Lib\site-packages\django\views\generic\base.py", line 143, in dispatch
    return handler(request, *args, **kwargs)
           ^^^^^^^^^^^^^^^^^^^^^^^^^^^^^^^^^
  File "C:\Users\Khusan Akhmedov\Documents\movie\.environment\Lib\site-packages\django\views\generic\list.py", line 174, in get
    context = self.get_context_data()
              ^^^^^^^^^^^^^^^^^^^^^^^
  File "C:\Users\Khusan Akhmedov\Documents\movie\apps\entry\views.py", line 91, in get_context_data
    caches = self.get_cache_keys()
             ^^^^^^^^^^^^^^^^^^^^^
  File "C:\Users\Khusan Akhmedov\Documents\movie\apps\entry\views.py", line 29, in get_cache_keys
    for key in cache:
TypeError: 'ConnectionProxy' object is not iterable
Internal Server Error: /
Traceback (most recent call last):
  File "C:\Users\Khusan Akhmedov\Documents\movie\.environment\Lib\site-packages\django\core\handlers\exception.py", line 55, in inner
    response = get_response(request)
               ^^^^^^^^^^^^^^^^^^^^^
  File "C:\Users\Khusan Akhmedov\Documents\movie\.environment\Lib\site-packages\django\core\handlers\base.py", line 197, in _get_response
    response = wrapped_callback(request, *callback_args, **callback_kwargs)
               ^^^^^^^^^^^^^^^^^^^^^^^^^^^^^^^^^^^^^^^^^^^^^^^^^^^^^^^^^^^^
  File "C:\Users\Khusan Akhmedov\Documents\movie\.environment\Lib\site-packages\django\views\generic\base.py", line 104, in view
    return self.dispatch(request, *args, **kwargs)
           ^^^^^^^^^^^^^^^^^^^^^^^^^^^^^^^^^^^^^^^
  File "C:\Users\Khusan Akhmedov\Documents\movie\.environment\Lib\site-packages\django\views\generic\base.py", line 143, in dispatch
    return handler(request, *args, **kwargs)
           ^^^^^^^^^^^^^^^^^^^^^^^^^^^^^^^^^
  File "C:\Users\Khusan Akhmedov\Documents\movie\.environment\Lib\site-packages\django\views\generic\list.py", line 174, in get
    context = self.get_context_data()
              ^^^^^^^^^^^^^^^^^^^^^^^
  File "C:\Users\Khusan Akhmedov\Documents\movie\apps\entry\views.py", line 92, in get_context_data
    caches = self.get_cache_keys()
             ^^^^^^^^^^^^^^^^^^^^^
  File "C:\Users\Khusan Akhmedov\Documents\movie\apps\entry\views.py", line 29, in get_cache_keys
    cache_keys = cache.keys('*')
                 ^^^^^^^^^^
  File "C:\Users\Khusan Akhmedov\Documents\movie\.environment\Lib\site-packages\django\utils\connection.py", line 15, in __getattr__
    return getattr(self._connections[self._alias], item)
           ^^^^^^^^^^^^^^^^^^^^^^^^^^^^^^^^^^^^^^^^^^^^^
AttributeError: 'LocMemCache' object has no attribute 'keys'
Internal Server Error: /
Traceback (most recent call last):
  File "C:\Users\Khusan Akhmedov\Documents\movie\.environment\Lib\site-packages\django\core\handlers\exception.py", line 55, in inner
    response = get_response(request)
               ^^^^^^^^^^^^^^^^^^^^^
  File "C:\Users\Khusan Akhmedov\Documents\movie\.environment\Lib\site-packages\django\core\handlers\base.py", line 197, in _get_response
    response = wrapped_callback(request, *callback_args, **callback_kwargs)
               ^^^^^^^^^^^^^^^^^^^^^^^^^^^^^^^^^^^^^^^^^^^^^^^^^^^^^^^^^^^^
  File "C:\Users\Khusan Akhmedov\Documents\movie\.environment\Lib\site-packages\django\views\generic\base.py", line 104, in view
    return self.dispatch(request, *args, **kwargs)
           ^^^^^^^^^^^^^^^^^^^^^^^^^^^^^^^^^^^^^^^
  File "C:\Users\Khusan Akhmedov\Documents\movie\.environment\Lib\site-packages\django\views\generic\base.py", line 143, in dispatch
    return handler(request, *args, **kwargs)
           ^^^^^^^^^^^^^^^^^^^^^^^^^^^^^^^^^
  File "C:\Users\Khusan Akhmedov\Documents\movie\.environment\Lib\site-packages\django\views\generic\list.py", line 174, in get
    context = self.get_context_data()
              ^^^^^^^^^^^^^^^^^^^^^^^
  File "C:\Users\Khusan Akhmedov\Documents\movie\apps\entry\views.py", line 88, in get_context_data
    caches = self.get_cache_keys()
             ^^^^^^^^^^^^^^^^^^^^^
  File "C:\Users\Khusan Akhmedov\Documents\movie\apps\entry\views.py", line 29, in get_cache_keys
    cache_keys = cache.keys('*')
                 ^^^^^^^^^^
  File "C:\Users\Khusan Akhmedov\Documents\movie\.environment\Lib\site-packages\django\utils\connection.py", line 15, in __getattr__
    return getattr(self._connections[self._alias], item)
           ^^^^^^^^^^^^^^^^^^^^^^^^^^^^^^^^^^^^^^^^^^^^^
AttributeError: 'FileBasedCache' object has no attribute 'keys'
Internal Server Error: /
Traceback (most recent call last):
  File "C:\Users\Khusan Akhmedov\Documents\movie\.environment\Lib\site-packages\django\core\handlers\exception.py", line 55, in inner
    response = get_response(request)
               ^^^^^^^^^^^^^^^^^^^^^
  File "C:\Users\Khusan Akhmedov\Documents\movie\.environment\Lib\site-packages\django\core\handlers\base.py", line 197, in _get_response
    response = wrapped_callback(request, *callback_args, **callback_kwargs)
               ^^^^^^^^^^^^^^^^^^^^^^^^^^^^^^^^^^^^^^^^^^^^^^^^^^^^^^^^^^^^
  File "C:\Users\Khusan Akhmedov\Documents\movie\.environment\Lib\site-packages\django\views\generic\base.py", line 104, in view
    return self.dispatch(request, *args, **kwargs)
           ^^^^^^^^^^^^^^^^^^^^^^^^^^^^^^^^^^^^^^^
  File "C:\Users\Khusan Akhmedov\Documents\movie\.environment\Lib\site-packages\django\views\generic\base.py", line 143, in dispatch
    return handler(request, *args, **kwargs)
           ^^^^^^^^^^^^^^^^^^^^^^^^^^^^^^^^^
  File "C:\Users\Khusan Akhmedov\Documents\movie\.environment\Lib\site-packages\django\views\generic\list.py", line 174, in get
    context = self.get_context_data()
              ^^^^^^^^^^^^^^^^^^^^^^^
  File "C:\Users\Khusan Akhmedov\Documents\movie\apps\entry\views.py", line 88, in get_context_data
    caches = self.get_cache_keys()
             ^^^^^^^^^^^^^^^^^^^^^
  File "C:\Users\Khusan Akhmedov\Documents\movie\apps\entry\views.py", line 29, in get_cache_keys
    cache_keys = cache.keys('*')
                 ^^^^^^^^^^
  File "C:\Users\Khusan Akhmedov\Documents\movie\.environment\Lib\site-packages\django\utils\connection.py", line 15, in __getattr__
    return getattr(self._connections[self._alias], item)
           ^^^^^^^^^^^^^^^^^^^^^^^^^^^^^^^^^^^^^^^^^^^^^
AttributeError: 'FileBasedCache' object has no attribute 'keys'
